<?xml version="1.0" ?>
<!-- =================================================================================== -->
<!-- |    This document was autogenerated by xacro from steer_bot.urdf.xacro           | -->
<!-- |    EDITING THIS FILE BY HAND IS NOT RECOMMENDED                                 | -->
<!-- =================================================================================== -->
<!--
Robot model adapted from https://github.com/CIR-KIT/steer_drive_ros/blob/kinetic-devel/steer_drive_controller/test/common/urdf/steerbot.xacro

Modifications:
Remove base_footprint link. Useful for navigation but not necessary for a simple example.
Added materials for URDF
Updated inertials

Geometry:
The Ackermann steering controllers require the longitudinal
separation between the front and back wheel axes and the
lateral separation between the left and right front steering axes.

For this model:
wheel_separation_h = base_length - 2 * axle_offset = 0.4
wheel_separation_w = base_width  + 2 * axle_offset = 0.4
-->
<robot name="steer_bot">
  <material name="red">
    <color rgba="0.8 0 0 1"/>
  </material>
  <material name="green">
    <color rgba="0 0.8 0 1"/>
  </material>
  <material name="blue">
    <color rgba="0 0 0.8 1"/>
  </material>
  <material name="yellow">
    <color rgba="0.8 0.8 0 1"/>
  </material>
  <material name="orange">
    <color rgba="0.8 0.25 0 1"/>
  </material>
  <material name="black">
    <color rgba="0 0 0 1"/>
  </material>
  <material name="dark_gray">
    <color rgba="0.5 0.5 0.5 1"/>
  </material>
  <material name="gray">
    <color rgba="0.753 0.753 0.753 1"/>
  </material>
  <material name="silver">
    <color rgba="0.88 0.88 0.88 1"/>
  </material>
  <material name="white">
    <color rgba="1 1 1 1"/>
  </material>
  <!-- Gazebo plugins -->
  <gazebo>
    <!-- Load ros_control plugin using the steer_bot_hardware_gazebo
         implementation of the hardware_interface::RobotHW -->
    <plugin filename="libgazebo_ros_control.so" name="gazebo_ros_control">
      <robotNamespace>/picar_bot</robotNamespace>
      <robotSimType>gazebo_ros_control/DefaultRobotHWSim</robotSimType>
      <legacyModeNS>false</legacyModeNS>
    </plugin>
  </gazebo>
  <!-- Base link -->
  <link name="base_link"/>
  <link name="chassis">
    <visual>
      <origin rpy="0 0 0" xyz="0 0 0"/>
      <geometry>
        <box size="0.5 0.3 0.1"/>
      </geometry>
      <material name="green"/>
    </visual>
    <collision>
      <origin rpy="0 0 0" xyz="0 0 0"/>
      <geometry>
        <box size="0.5 0.3 0.1"/>
      </geometry>
    </collision>
    <inertial>
      <origin rpy="0 0 0" xyz="0 0 0"/>
      <mass value="5"/>
      <inertia ixx="0.041666666666666664" ixy="0.0" ixz="0.0" iyy="0.10833333333333334" iyz="0.0" izz="0.14166666666666664"/>
    </inertial>
  </link>
  <joint name="joint_chassis_to_base_link" type="fixed">
    <parent link="base_link"/>
    <child link="chassis"/>
  </joint>
  <link name="front_steer_link">
    <visual>
      <origin rpy="0 0 0" xyz="0 0 0"/>
      <geometry>
        <cylinder length="0.02" radius="0.05"/>
      </geometry>
      <material name="yellow"/>
    </visual>
    <collision>
      <origin rpy="0 0 0" xyz="0 0 0"/>
      <geometry>
        <cylinder length="0.02" radius="0.05"/>
      </geometry>
    </collision>
    <inertial>
      <origin rpy="0 0 0" xyz="0 0 0"/>
      <mass value="1"/>
      <inertia ixx="0.0006583333333333334" ixy="0.0" ixz="0.0" iyy="0.0006583333333333334" iyz="0.0" izz="0.0012500000000000002"/>
    </inertial>
  </link>
  <joint name="front_steer_joint" type="revolute">
    <parent link="base_link"/>
    <child link="front_steer_link"/>
    <origin rpy="0 0 0" xyz="0.2 0 0.12000000000000001"/>
    <axis xyz="0 0 1"/>
    <limit effort="10.0" lower="-3.141592653589793" upper="3.141592653589793" velocity="5.0"/>
  </joint>
  <transmission name="front_steer_joint_trans">
    <type>transmission_interface/SimpleTransmission</type>
    <actuator name="front_steer_joint_motor">
      <mechanicalReduction>1</mechanicalReduction>
      <hardwareInterface>hardware_interface/PositionJointInterface</hardwareInterface>
    </actuator>
    <joint name="front_steer_joint">
      <hardwareInterface>hardware_interface/PositionJointInterface</hardwareInterface>
    </joint>
  </transmission>
  <gazebo reference="front_steer_link">
    <material>Gazebo/Yellow</material>
  </gazebo>
  <link name="rear_wheel_link">
    <visual>
      <origin rpy="0 0 0" xyz="0 0 0"/>
      <geometry>
        <cylinder length="0.04" radius="0.025"/>
      </geometry>
      <material name="yellow"/>
    </visual>
    <collision>
      <origin rpy="0 0 0" xyz="0 0 0"/>
      <geometry>
        <cylinder length="0.04" radius="0.025"/>
      </geometry>
    </collision>
    <inertial>
      <origin rpy="0 0 0" xyz="0 0 0"/>
      <mass value="0.03125"/>
      <inertia ixx="9.049479166666668e-06" ixy="0.0" ixz="0.0" iyy="9.049479166666668e-06" iyz="0.0" izz="9.765625000000002e-06"/>
    </inertial>
  </link>
  <joint name="rear_wheel_joint" type="continuous">
    <parent link="base_link"/>
    <child link="rear_wheel_link"/>
    <origin rpy="-1.5707963267948966 0 0" xyz="-0.2 0 0"/>
    <axis xyz="0 0 1"/>
  </joint>
  <transmission name="rear_wheel_joint_trans">
    <type>transmission_interface/SimpleTransmission</type>
    <actuator name="rear_wheel_joint_motor">
      <mechanicalReduction>1</mechanicalReduction>
      <hardwareInterface>hardware_interface/VelocityJointInterface</hardwareInterface>
    </actuator>
    <joint name="rear_wheel_joint">
      <hardwareInterface>hardware_interface/VelocityJointInterface</hardwareInterface>
    </joint>
  </transmission>
  <gazebo reference="rear_wheel_link">
    <material>Gazebo/Yellow</material>
  </gazebo>
  <link name="front_right_steer_link">
    <visual>
      <origin rpy="0 0 0" xyz="0 0 0"/>
      <geometry>
        <cylinder length="0.02" radius="0.05"/>
      </geometry>
      <material name="blue"/>
    </visual>
    <collision>
      <origin rpy="0 0 0" xyz="0 0 0"/>
      <geometry>
        <cylinder length="0.02" radius="0.05"/>
      </geometry>
    </collision>
    <inertial>
      <origin rpy="0 0 0" xyz="0 0 0"/>
      <mass value="1"/>
      <inertia ixx="0.0006583333333333334" ixy="0.0" ixz="0.0" iyy="0.0006583333333333334" iyz="0.0" izz="0.0012500000000000002"/>
    </inertial>
  </link>
  <joint name="front_right_steer_joint" type="revolute">
    <parent link="base_link"/>
    <child link="front_right_steer_link"/>
    <origin rpy="0 0 0" xyz="0.2 -0.2 0.12000000000000001"/>
    <axis xyz="0 0 1"/>
    <limit effort="10.0" lower="-3.141592653589793" upper="3.141592653589793" velocity="5.0"/>
  </joint>
  <link name="front_right_wheel_link">
    <visual>
      <origin rpy="0 0 0" xyz="0 0 0"/>
      <geometry>
        <cylinder length="0.08" radius="0.1"/>
      </geometry>
      <material name="red"/>
    </visual>
    <collision>
      <origin rpy="0 0 0" xyz="0 0 0"/>
      <geometry>
        <cylinder length="0.08" radius="0.1"/>
      </geometry>
    </collision>
    <inertial>
      <origin rpy="0 0 0" xyz="0 0 0"/>
      <mass value="1"/>
      <inertia ixx="0.003033333333333334" ixy="0.0" ixz="0.0" iyy="0.003033333333333334" iyz="0.0" izz="0.005000000000000001"/>
    </inertial>
  </link>
  <joint name="front_right_wheel_joint" type="continuous">
    <parent link="front_right_steer_link"/>
    <child link="front_right_wheel_link"/>
    <origin rpy="-1.5707963267948966 0 0" xyz="0 0 -0.12000000000000001"/>
    <axis xyz="0 0 1"/>
  </joint>
  <transmission name="front_right_steer_joint_trans">
    <type>transmission_interface/SimpleTransmission</type>
    <actuator name="front_right_steer_joint_motor">
      <mechanicalReduction>1</mechanicalReduction>
      <hardwareInterface>hardware_interface/PositionJointInterface</hardwareInterface>
    </actuator>
    <joint name="front_right_steer_joint">
      <hardwareInterface>hardware_interface/PositionJointInterface</hardwareInterface>
    </joint>
  </transmission>
  <transmission name="front_right_wheel_joint_trans">
    <type>transmission_interface/SimpleTransmission</type>
    <actuator name="front_right_wheel_joint_motor">
      <mechanicalReduction>1</mechanicalReduction>
      <hardwareInterface>hardware_interface/VelocityJointInterface</hardwareInterface>
    </actuator>
    <joint name="front_right_wheel_joint">
      <hardwareInterface>hardware_interface/VelocityJointInterface</hardwareInterface>
    </joint>
  </transmission>
  <gazebo reference="front_right_steer_link">
    <material>Gazebo/Blue</material>
  </gazebo>
  <gazebo reference="front_right_wheel_link">
    <material>Gazebo/Red</material>
  </gazebo>
  <link name="front_left_steer_link">
    <visual>
      <origin rpy="0 0 0" xyz="0 0 0"/>
      <geometry>
        <cylinder length="0.02" radius="0.05"/>
      </geometry>
      <material name="blue"/>
    </visual>
    <collision>
      <origin rpy="0 0 0" xyz="0 0 0"/>
      <geometry>
        <cylinder length="0.02" radius="0.05"/>
      </geometry>
    </collision>
    <inertial>
      <origin rpy="0 0 0" xyz="0 0 0"/>
      <mass value="1"/>
      <inertia ixx="0.0006583333333333334" ixy="0.0" ixz="0.0" iyy="0.0006583333333333334" iyz="0.0" izz="0.0012500000000000002"/>
    </inertial>
  </link>
  <joint name="front_left_steer_joint" type="revolute">
    <parent link="base_link"/>
    <child link="front_left_steer_link"/>
    <origin rpy="0 0 0" xyz="0.2 0.2 0.12000000000000001"/>
    <axis xyz="0 0 1"/>
    <limit effort="10.0" lower="-3.141592653589793" upper="3.141592653589793" velocity="5.0"/>
  </joint>
  <link name="front_left_wheel_link">
    <visual>
      <origin rpy="0 0 0" xyz="0 0 0"/>
      <geometry>
        <cylinder length="0.08" radius="0.1"/>
      </geometry>
      <material name="red"/>
    </visual>
    <collision>
      <origin rpy="0 0 0" xyz="0 0 0"/>
      <geometry>
        <cylinder length="0.08" radius="0.1"/>
      </geometry>
    </collision>
    <inertial>
      <origin rpy="0 0 0" xyz="0 0 0"/>
      <mass value="1"/>
      <inertia ixx="0.003033333333333334" ixy="0.0" ixz="0.0" iyy="0.003033333333333334" iyz="0.0" izz="0.005000000000000001"/>
    </inertial>
  </link>
  <joint name="front_left_wheel_joint" type="continuous">
    <parent link="front_left_steer_link"/>
    <child link="front_left_wheel_link"/>
    <origin rpy="-1.5707963267948966 0 0" xyz="0 0 -0.12000000000000001"/>
    <axis xyz="0 0 1"/>
  </joint>
  <transmission name="front_left_steer_joint_trans">
    <type>transmission_interface/SimpleTransmission</type>
    <actuator name="front_left_steer_joint_motor">
      <mechanicalReduction>1</mechanicalReduction>
      <hardwareInterface>hardware_interface/PositionJointInterface</hardwareInterface>
    </actuator>
    <joint name="front_left_steer_joint">
      <hardwareInterface>hardware_interface/PositionJointInterface</hardwareInterface>
    </joint>
  </transmission>
  <transmission name="front_left_wheel_joint_trans">
    <type>transmission_interface/SimpleTransmission</type>
    <actuator name="front_left_wheel_joint_motor">
      <mechanicalReduction>1</mechanicalReduction>
      <hardwareInterface>hardware_interface/VelocityJointInterface</hardwareInterface>
    </actuator>
    <joint name="front_left_wheel_joint">
      <hardwareInterface>hardware_interface/VelocityJointInterface</hardwareInterface>
    </joint>
  </transmission>
  <gazebo reference="front_left_steer_link">
    <material>Gazebo/Blue</material>
  </gazebo>
  <gazebo reference="front_left_wheel_link">
    <material>Gazebo/Red</material>
  </gazebo>
  <link name="rear_right_wheel_link">
    <visual>
      <origin rpy="0 0 0" xyz="0 0 0"/>
      <geometry>
        <cylinder length="0.08" radius="0.1"/>
      </geometry>
      <material name="red"/>
    </visual>
    <collision>
      <origin rpy="0 0 0" xyz="0 0 0"/>
      <geometry>
        <cylinder length="0.08" radius="0.1"/>
      </geometry>
    </collision>
    <inertial>
      <origin rpy="0 0 0" xyz="0 0 0"/>
      <mass value="1"/>
      <inertia ixx="0.003033333333333334" ixy="0.0" ixz="0.0" iyy="0.003033333333333334" iyz="0.0" izz="0.005000000000000001"/>
    </inertial>
  </link>
  <joint name="rear_right_wheel_joint" type="continuous">
    <parent link="base_link"/>
    <child link="rear_right_wheel_link"/>
    <origin rpy="-1.5707963267948966 0 0" xyz="-0.2 -0.2 0"/>
    <axis xyz="0 0 1"/>
  </joint>
  <transmission name="rear_right_wheel_joint_trans">
    <type>transmission_interface/SimpleTransmission</type>
    <actuator name="rear_right_wheel_joint_motor">
      <mechanicalReduction>1</mechanicalReduction>
      <hardwareInterface>hardware_interface/VelocityJointInterface</hardwareInterface>
    </actuator>
    <joint name="rear_right_wheel_joint">
      <hardwareInterface>hardware_interface/VelocityJointInterface</hardwareInterface>
    </joint>
  </transmission>
  <gazebo reference="rear_right_wheel_link">
    <material>Gazebo/Red</material>
  </gazebo>
  <link name="rear_left_wheel_link">
    <visual>
      <origin rpy="0 0 0" xyz="0 0 0"/>
      <geometry>
        <cylinder length="0.08" radius="0.1"/>
      </geometry>
      <material name="red"/>
    </visual>
    <collision>
      <origin rpy="0 0 0" xyz="0 0 0"/>
      <geometry>
        <cylinder length="0.08" radius="0.1"/>
      </geometry>
    </collision>
    <inertial>
      <origin rpy="0 0 0" xyz="0 0 0"/>
      <mass value="1"/>
      <inertia ixx="0.003033333333333334" ixy="0.0" ixz="0.0" iyy="0.003033333333333334" iyz="0.0" izz="0.005000000000000001"/>
    </inertial>
  </link>
  <joint name="rear_left_wheel_joint" type="continuous">
    <parent link="base_link"/>
    <child link="rear_left_wheel_link"/>
    <origin rpy="-1.5707963267948966 0 0" xyz="-0.2 0.2 0"/>
    <axis xyz="0 0 1"/>
  </joint>
  <transmission name="rear_left_wheel_joint_trans">
    <type>transmission_interface/SimpleTransmission</type>
    <actuator name="rear_left_wheel_joint_motor">
      <mechanicalReduction>1</mechanicalReduction>
      <hardwareInterface>hardware_interface/VelocityJointInterface</hardwareInterface>
    </actuator>
    <joint name="rear_left_wheel_joint">
      <hardwareInterface>hardware_interface/VelocityJointInterface</hardwareInterface>
    </joint>
  </transmission>
  <gazebo reference="rear_left_wheel_link">
    <material>Gazebo/Red</material>
  </gazebo>
  <!-- Colour -->
  <gazebo reference="chassis">
    <material>Gazebo/Green</material>
  </gazebo>
  <link name="lidar_cylinder">
    <visual>
      <material name="green"/>
      <geometry>
        <cylinder length="0.1" radius="0.05"/>
      </geometry>
    </visual>
    <collision>
      <geometry>
        <cylinder length="0.1" radius="0.05"/>
      </geometry>
    </collision>
    <inertial>
      <origin rpy="0 0 0" xyz="0 0 0.2"/>
      <mass value="0.05"/>
      <inertia ixx="7.291666666666667e-05" ixy="0.0" ixz="0.0" iyy="7.291666666666667e-05" iyz="0.0" izz="6.250000000000001e-05"/>
    </inertial>
  </link>
  <joint name="joint_lidar_cylinder" type="fixed">
    <origin xyz="0 0 0.2"/>
    <parent link="base_link"/>
    <child link="lidar_cylinder"/>
  </joint>
  <!-- Lidar (YD X4 Lidar) -->
  <gazebo reference="lidar_cylinder">
    <material>Gazebo/Green</material>
  </gazebo>
  <gazebo reference="lidar_cylinder">
    <sensor name="lds_lfcd_sensor" type="ray">
      <pose>0 0 0.0 0 0 0</pose>
      <visualize>false</visualize>
      <update_rate>5</update_rate>
      <ray>
        <scan>
          <horizontal>
            <samples>720</samples>
            <resolution>0.5</resolution>
            <min_angle>0.0</min_angle>
            <max_angle>6.28319</max_angle>
          </horizontal>
        </scan>
        <range>
          <min>0.12</min>
          <max>10</max>
          <resolution>0.015</resolution>
        </range>
        <noise>
          <type>gaussian</type>
          <!-- Noise parameters based on published spec for YDLIDAR X4
               is 1.5% at half range 4m (= 60mm, "+-160mm" accuracy at max. range 8m).
               A mean of 0.0m and stddev of 0.020m will put 99.7% of samples
               within 0.16m of the true reading. -->
          <mean>0.0</mean>
          <stddev>0.02</stddev>
        </noise>
      </ray>
      <plugin filename="libgazebo_ros_laser.so" name="gazebo_ros_lds_lfcd_controller">
        <!-- <topicName>/gopigo/scan</topicName> -->
        <topicName>scan</topicName>
        <frameName>lidar_cylinder</frameName>
      </plugin>
    </sensor>
  </gazebo>
  <!-- Camera -->
  <link name="camera_box">
    <visual>
      <material name="blue"/>
      <geometry>
        <box size="0.05 0.05 0.05"/>
      </geometry>
    </visual>
    <collision>
      <geometry>
        <box size="0.05 0.05 0.05"/>
      </geometry>
    </collision>
    <inertial>
      <origin rpy="0 0 0" xyz="0.05 0.05 0.05"/>
      <mass value="0.1"/>
      <inertia ixx="2.083333333333334e-05" ixy="0.0" ixz="0.0" iyy="0.0005416666666666668" iyz="0.0" izz="0.0005208333333333333"/>
    </inertial>
  </link>
  <joint name="joint_camera_box" type="fixed">
    <origin rpy="0 0 0" xyz="0.25 0.0 0.05"/>
    <parent link="chassis"/>
    <child link="camera_box"/>
  </joint>
  <gazebo reference="camera_box">
    <sensor name="camera1" type="camera">
      <update_rate>30.0</update_rate>
      <camera name="front">
        <horizontal_fov>1.3962634</horizontal_fov>
        <image>
          <width>800</width>
          <height>800</height>
          <format>R8G8B8</format>
        </image>
        <clip>
          <near>0.02</near>
          <far>300</far>
        </clip>
      </camera>
      <plugin filename="libgazebo_ros_camera.so" name="camera_controller">
        <alwaysOn>true</alwaysOn>
        <updateRate>0.0</updateRate>
        <cameraName>/camera1</cameraName>
        <imageTopicName>image_raw</imageTopicName>
        <cameraInfoTopicName>camera_info</cameraInfoTopicName>
        <frameName>camera</frameName>
        <hackBaseline>0.07</hackBaseline>
        <distortionK1>0.0</distortionK1>
        <distortionK2>0.0</distortionK2>
        <distortionK3>0.0</distortionK3>
        <distortionT1>0.0</distortionT1>
        <distortionT2>0.0</distortionT2>
      </plugin>
    </sensor>
  </gazebo>
  <!-- IMU -->
  <!-- Imu -->
  <link name="imu_box">
    <visual>
      <material name="blue"/>
      <geometry>
        <box size="0.05 0.05 0.05"/>
      </geometry>
    </visual>
    <collision>
      <geometry>
        <box size="0.05 0.05 0.05"/>
      </geometry>
    </collision>
    <inertial>
      <origin rpy="0 0 0" xyz="0.05 0.05 0.05"/>
      <mass value="0.1"/>
      <inertia ixx="2.083333333333334e-05" ixy="0.0" ixz="0.0" iyy="2.083333333333334e-05" iyz="0.0" izz="0.0"/>
    </inertial>
  </link>
  <joint name="joint_imu_box" type="fixed">
    <origin rpy="0 0 0" xyz="0 0.0 0.05"/>
    <parent link="chassis"/>
    <child link="imu_box"/>
  </joint>
  <gazebo reference="imu_box">
    <gravity>true</gravity>
    <sensor name="imu_sensor" type="imu">
      <always_on>true</always_on>
      <update_rate>100</update_rate>
      <visualize>true</visualize>
      <topic>__default_topic__</topic>
      <plugin filename="libgazebo_ros_imu_sensor.so" name="imu_plugin">
        <topicName>imu</topicName>
        <bodyName>imu_link</bodyName>
        <updateRateHZ>10.0</updateRateHZ>
        <gaussianNoise>2.89e-08</gaussianNoise>
        <xyzOffset>0 0 0</xyzOffset>
        <rpyOffset>0 0 0</rpyOffset>
        <frameName>imu_link</frameName>
        <inertialOrientationAsReference>false</inertialOrientationAsReference>
      </plugin>
      <pose>0 0 0 0 0 0</pose>
    </sensor>
  </gazebo>
  <!-- GPS Sensor -->
  <!--...................................GPS MODULE...................................................-->
  <link name="base_gps_front">
    <inertial>
      <mass value="1e-5"/>
      <origin rpy="0 0 0" xyz="0 0 0"/>
      <inertia ixx="1e-6" ixy="0" ixz="0" iyy="1e-6" iyz="0" izz="1e-6"/>
    </inertial>
    <collision name="collision">
      <geometry>
        <box size="0.01 0.01 0.01"/>
      </geometry>
      <origin rpy="0 0 0" xyz="0 0 0"/>
      <material name="green"/>
    </collision>
    <visual>
      <geometry>
        <box size="0.01 0.01 0.01"/>
      </geometry>
      <origin rpy="0 0 0" xyz="0 0 0"/>
      <material name="green"/>
    </visual>
  </link>
  <gazebo reference="base_gps_front">
    <material>Gazebo/Green</material>
    <turnGravityOff>false</turnGravityOff>
  </gazebo>
  <joint name="gps_front_joint" type="fixed">
    <axis xyz="0 1 0"/>
    <origin rpy="0 0 0" xyz="-0.395 -0.295 0.155"/>
    <parent link="base_link"/>
    <child link="base_gps_front"/>
  </joint>
  <!--..................................GPS SENSOR PLUGIN.......................................-->
  <!-- GPS Sensor -->
  <gazebo>
    <plugin filename="libhector_gazebo_ros_gps.so" name="novatel_gps_sim">
      <alwaysOn>1</alwaysOn>
      <updateRate>50</updateRate>
      <bodyName>base_gps_front</bodyName>
      <topicName>fix</topicName>
      <velocityTopicName>/vel</velocityTopicName>
      <drift>5.0 5.0 5.0</drift>
      <gaussianNoise>0.1 0.1 0.1</gaussianNoise>
      <velocityDrift>0 0 0</velocityDrift>
      <velocityGaussianNoise>0.1 0.1 0.1</velocityGaussianNoise>
      <!--<referenceLatitude>38.419354</referenceLatitude>-->
      <!--<referenceLongitude>-110.781900</referenceLongitude-->
      <!--for blacklister-->
      <!--<referenceLatitude>38.419853</referenceLatitude>
     <referenceLongitude>-110.781529</referenceLongitude>   for blacklister 1,2-->
      <!-- <referenceLatitude>13.347590</referenceLatitude> -->
      <!-- <referenceLongitude>74.79208833</referenceLongitude>   <!-\-for workshop-\-> -->
    </plugin>
  </gazebo>
</robot>
